Workbook

Sheet Bilgi
A1: TRENDYOL KÂRLILIK — BUYBOX ÇAPALI ÖNERİ MOTORU
A3: Komisyon Tarifeleri | B3: Trendyol'un haftalık komisyon Excel'ini A1'den itibaren buraya yapıştır (35 kolonlu çift dönemli format). Satır SİLME, içerik temizle.
A4: Maliyetler | B4: C=alış maliyeti, D=desi, E=BUYBOX fiyatı (manuel). Eşleşme barkodla.
A5: Hedefler | B5: Kategori başına MİN kâr %% ve HEDEF kâr %%. Mobilya tipi kategorilere 40%/40%, elektroniğe 4%/10% gir — öneri motoru buradan okur. Listede olmayan kategori için varsayılan: min %4 / hedef %10.
A6: KÂRLILIK / Öneri mantığı | B6: 1) Buybox girilmişse: buybox'ın 1 TL altı denenir; o fiyatın düştüğü baremin komisyonuyla kâr %% ≥ MİN kâr ise ÖNERİ = buybox altı ("BUYBOX'A GİR"). 2) Buybox altı min kârı korumuyorsa: min kârı koruyan EN DÜŞÜK fiyat önerilir (tüm baremler taranır, en ucuz uygun barem seçilir). 3) Buybox girilmemişse: HEDEF kârı koruyan en düşük fiyat önerilir.
A7: Dönem seçici | B7: KÂRLILIK AL1 hücresi: 1 = ilk tarife dönemi, 2 = ikinci dönem. Tüm hesap seçili dönemin komisyonlarıyla yapılır.
A8: Not | B8: Kâr %% satış fiyatı üzerindendir. Kargo: fiyat ≤199,99→47,40; 200-399,99→85,40; üstü desi tarifesi. En düşük fiyat hesabında desi kargosu varsayılır (400 TL üstü ürünlerde birebir doğru).
A13: PLUS + Güncelleme | B13: Plus tarifesi turuncu blokta: Plus limit fiyatında satarsan komisyon/kâr ve mevcut öneriyle farkı. GÜNCELLEME: tarife dosyalarını Downloads'a indir → masaüstündeki "Trendyol Güncelle.command"a çift tıkla. Script en yeni normal+Plus dosyayı içerikten tanır, sekmelere işler, API fiyat/stok senkronunu çalıştırır ve dosyayı açar. Yapıştırma yok.

Sheet Komisyon Tarifeleri
A1: ÜRÜN İSMİ | B1: BARKOD | C1: SATICI STOK KODU | D1: BEDEN | E1: MODEL KODU | F1: KATEGORİ | G1: MARKA | H1: STOK | I1: 1.Fiyat Alt Limit | J1: 2.Fiyat Üst Limiti | K1: 2.Fiyat Alt Limit | L1: 3.Fiyat Üst Limiti | M1: 3.Fiyat Alt Limit | N1: 4.Fiyat Üst Limiti | O1: Tarih aralığı (3 Gün) | P1: 1.KOMİSYON | Q1: 2.KOMİSYON | R1: 3.KOMİSYON | S1: 4.KOMİSYON | T1: Tarih aralığı (4 Gün) | U1: 1.KOMİSYON | V1: 2.KOMİSYON | W1: 3.KOMİSYON | X1: 4.KOMİSYON | Y1: KOMİSYONA ESAS FİYAT | Z1: GÜNCEL KOMİSYON | AA1: GÜNCEL TSF | AB1: YENİ TSF (FİYAT GÜNCELLE) | AC1: Hesaplanan Komisyon (3 Gün) | AD1: Hesaplanan Komisyon (4 Gün) | AE1: Tarife Seçimi | AF1: FIRST EXTERNAL ID | AG1: SECOND EXTERNAL ID | AH1: FULL EXTERNAL ID | AI1: TARİFE GRUBU

Sheet Kargo
A1: Desi | B1: Trendyol Kargo (TL, KDV dahil) — Aras 10.08.2026 | C1: HB Kargo (TL) | D1: Fiyat baremli kargo
A2: 1 | B2: 106.75 | C2: 106.8 | D2: Fiyat 0-199,99 | E2: 47.4
A3: 2 | B3: 106.75 | C3: 106.8 | D3: Fiyat 200-399,99 | E3: 85.4
A4: 3 | B4: 121.01 | C4: 125.4
A5: 4 | B5: 131.88 | C5: 134.81
A6: 5 | B6: 141.42 | C6: 142.99
A7: 6 | B7: 154.07 | C7: 153.86
A8: 7 | B8: 163.4 | C8: 163.32
A9: 8 | B9: 174.32 | C9: 171.85
A10: 9 | B10: 184.32 | C10: 182.27
A11: 10 | B11: 197.08 | C11: 191.54
A12: 11 | B12: 207.71 | C12: 199.5
A13: 12 | B13: 215.36 | C13: 207.58
A14: 13 | B14: 225.13 | C14: 225
A15: 14 | B15: 233.81 | C15: 229.8
... A21: 20 | B21: 302.51 | C21: 303.2
A22: 21 | B22: 317.76
A23: 22 | B23: 331.68
A24: 23 | B24: 345.56
A25: 24 | B25: 357.91
A26: 25 | B26: 370.2
A27: 26 | B27: 387.42
A28: 27 | B28: 403.13
A29: 28 | B29: 417.19
A30: 29 | B30: 433.31
A31: 30 | B31: 445.61
A32: 31 | B32: 459.74
A33: 32 | B33: 473.88
... A61: 60 | B61: 869.7

Sheet Maliyetler
A1: Barkod | B1: Ürün Adı | C1: Alış Maliyeti (TL) | D1: Desi | E1: Buybox Fiyatı (TL) | F1: Canlı Satış Fiyatı (API) | G1: Canlı Stok (API) | H1: API Güncelleme | I1: Maliyet Kaynağı | K1: Desi Kaynağı | M1: Kategori | N1: Komisyon (API) | O1: Buybox Sırası | P1: Rakip Var

Sheet Hedefler
A1: Kategori | B1: Min Kâr % | C1: Hedef Kâr % | D1: Tavan Kâr %

Sheet KÂRLILIK
A1: Ürün | B1: Barkod | C1: Kategori | D1: Maliyet | E1: Desi | F1: Kargo(desi) | G1: B1 Fiyat(TSF) | H1: B1 Kom% | I1: B1 Kâr TL | J1: B1 Kâr% | K1: B2 Fiyat | L1: B2 Kom% | M1: B2 Kâr TL | N1: B2 Kâr% | O1: B3 Fiyat | P1: B3 Kom% | Q1: B3 Kâr TL | R1: B3 Kâr% | S1: B4 Fiyat | T1: B4 Kom% | U1: B4 Kâr TL | V1: B4 Kâr% | W1: Min Kâr% | X1: Hedef Kâr% | Y1: BUYBOX | Z1: BB Altı Fiyat | AA1: BB Altı Kom% | AB1: BB Altı Kâr TL | AC1: BB Altı Kâr% | AD1: Min Fiyat (min kâr) | AE1: Min Fiyat (hedef kâr) | AF1: ÖNERİLEN FİYAT | AG1: ÖNERİ KÂR TL | AH1: ÖNERİ KÂR % | AI1: DURUM | AJ1: CANLI FİYAT (API) | AK1: CANLI STOK | AL1: DÖNEM SEÇ (1/2) → | AM1: 1 | AN1: =IF($AM$1=2,'Komisyon Tarifeleri'!T2,'Komisyon Tarifeleri'!O2) | AO1: PLUS Limit Fiyat | AP1: PLUS Kom% | AQ1: PLUS Kâr TL | AR1: PLUS Kâr % | AS1: PLUS − ÖNERİ (TL)
A2: =IF('Komisyon Tarifeleri'!A2="","",'Komisyon Tarifeleri'!A2) | B2: =IF('Komisyon Tarifeleri'!B2="","",'Komisyon Tarifeleri'!B2&"") | C2: =IF($B2="","",'Komisyon Tarifeleri'!F2) | D2: =IF($B2="","",IFERROR(VLOOKUP($B2,Maliyetler!$A:$E,3,FALSE),"")) | E2: =IF($B2="","",IFERROR(VLOOKUP($B2,Maliyetler!$A:$E,4,FALSE),1)) | F2: =IF($B2="","",IFERROR(VLOOKUP(MIN(20,MAX(1,ROUND($E2,0))),Kargo!$A:$B,2,FALSE),99.46)) | G2: =IF($B2="","",IF(IF(N('Komisyon Tarifeleri'!AA2)>='Komisyon Tarifeleri'!I2,'Komisyon Tarifeleri'!AA2,'Komisyon Tarifeleri'!I2)="","",IF(N('Komisyon Tarifeleri'!AA2)>='Komisyon Tarifeleri'!I2,'Komisyon Tarifeleri'!AA2,'Komisyon Tarifeleri'!I2))) | H2: =IF(G2="","",IF($AM$1=2,'Komisyon Tarifeleri'!U2,'Komisyon Tarifeleri'!P2)) | I2: =IF(OR(G2="",$D2=""),"",G2*(1-H2/100)-$D2-IF(G2<=199.99,Kargo!$E$2,IF(G2<=399.99,Kargo!$E$3,$F2))) | J2: =IF(I2="","",I2/G2) | K2: =IF($B2="","",IF('Komisyon Tarifeleri'!J2="","",'Komisyon Tarifeleri'!J2)) | L2: =IF(K2="","",IF($AM$1=2,'Komisyon Tarifeleri'!V2,'Komisyon Tarifeleri'!Q2)) | M2: =IF(OR(K2="",$D2=""),"",K2*(1-L2/100)-$D2-IF(K2<=199.99,Kargo!$E$2,IF(K2<=399.99,Kargo!$E$3,$F2))) | N2: =IF(M2="","",M2/K2) | O2: =IF($B2="","",IF('Komisyon Tarifeleri'!L2="","",'Komisyon Tarifeleri'!L2)) | P2: =IF(O2="","",IF($AM$1=2,'Komisyon Tarifeleri'!W2,'Komisyon Tarifeleri'!R2)) | Q2: =IF(OR(O2="",$D2=""),"",O2*(1-P2/100)-$D2-IF(O2<=199.99,Kargo!$E$2,IF(O2<=399.99,Kargo!$E$3,$F2))) | R2: =IF(Q2="","",Q2/O2) | S2: =IF($B2="","",IF('Komisyon Tarifeleri'!N2="","",'Komisyon Tarifeleri'!N2)) | T2: =IF(S2="","",IF($AM$1=2,'Komisyon Tarifeleri'!X2,'Komisyon Tarifeleri'!S2)) | U2: =IF(OR(S2="",$D2=""),"",S2*(1-T2/100)-$D2-IF(S2<=199.99,Kargo!$E$2,IF(S2<=399.99,Kargo!$E$3,$F2))) | V2: =IF(U2="","",U2/S2) | W2: =IF($B2="","",IFERROR(VLOOKUP($C2,Hedefler!$A:$C,2,FALSE),0.04)) | X2: =IF($B2="","",IFERROR(VLOOKUP($C2,Hedefler!$A:$C,3,FALSE),0.1)) | Y2: =IF($B2="","",IFERROR(VLOOKUP($B2,Maliyetler!$A:$E,5,FALSE),"")) | Z2: =IF(OR(Y2="",Y2=0),"",Y2-1) | AA2: =IF(Z2="","",IF(Z2>='Komisyon Tarifeleri'!I2,IF($AM$1=2,'Komisyon Tarifeleri'!U2,'Komisyon Tarifeleri'!P2),IF(Z2>='Komisyon Tarifeleri'!K2,IF($AM$1=2,'Komisyon Tarifeleri'!V2,'Komisyon Tarifeleri'!Q2),IF(Z2>='Komisyon Tarifeleri'!M2,IF($AM$1=2,'Komisyon Tarifeleri'!W2,'Komisyon Tarifeleri'!R2),IF($AM$1=2,'Komisyon Tarifeleri'!X2,'Komisyon Tarifeleri'!S2))))) | AB2: =IF(OR(AA2="",$D2=""),"",Z2*(1-AA2/100)-$D2-IF(Z2<=199.99,Kargo!$E$2,IF(Z2<=399.99,Kargo!$E$3,$F2))) | AC2: =IF(AB2="","",AB2/Z2) | AD2: =IF(OR($D2="",$B2=""),"",IF(AND((1-T2/100-W2)>0,CEILING(($D2+$F2)/(1-T2/100-W2),1)<='Komisyon Tarifeleri'!N2),CEILING(($D2+$F2)/(1-T2/100-W2),1),IF(AND((1-P2/100-W2)>0,CEILING(MAX('Komisyon Tarifeleri'!M2,($D2+$F2)/(1-P2/100-W2)),1)<='Komisyon Tarifeleri'!L2),CEILING(MAX('Komisyon Tarifeleri'!M2,($D2+$F2)/(1-P2/100-W2)),1),IF(AND((1-L2/100-W2)>0,CEILING(MAX('Komisyon Tarifeleri'!K2,($D2+$F2)/(1-L2/100-W2)),1)<='Komisyon Tarifeleri'!J2),CEILING(MAX('Komisyon Tarifeleri'!K2,($D2+$F2)/(1-L2/100-W2)),1),IF((1-H2/100-W2)>0,CEILING(MAX('Komisyon Tarifeleri'!I2,($D2+$F2)/(1-H2/100-W2)),1),"İMKÂNSIZ"))))) | AE2: =IF(OR($D2="",$B2=""),"",IF(AND((1-T2/100-X2)>0,CEILING(($D2+$F2)/(1-T2/100-X2),1)<='Komisyon Tarifeleri'!N2),CEILING(($D2+$F2)/(1-T2/100-X2),1),IF(AND((1-P2/100-X2)>0,CEILING(MAX('Komisyon Tarifeleri'!M2,($D2+$F2)/(1-P2/100-X2)),1)<='Komisyon Tarifeleri'!L2),CEILING(MAX('Komisyon Tarifeleri'!M2,($D2+$F2)/(1-P2/100-X2)),1),IF(AND((1-L2/100-X2)>0,CEILING(MAX('Komisyon Tarifeleri'!K2,($D2+$F2)/(1-L2/100-X2)),1)<='Komisyon Tarifeleri'!J2),CEILING(MAX('Komisyon Tarifeleri'!K2,($D2+$F2)/(1-L2/100-X2)),1),IF((1-H2/100-X2)>0,CEILING(MAX('Komisyon Tarifeleri'!I2,($D2+$F2)/(1-H2/100-X2)),1),"İMKÂNSIZ"))))) | AF2: =IF($D2="","",IF(AND(Y2<>"",AC2<>"",AC2>=W2),Z2,IF(Y2<>"",AD2,AE2))) | AG2: =IF(OR(AF2="",AF2="İMKÂNSIZ"),"",AF2*(1-IF(AF2>='Komisyon Tarifeleri'!I2,IF($AM$1=2,'Komisyon Tarifeleri'!U2,'Komisyon Tarifeleri'!P2),IF(AF2>='Komisyon Tarifeleri'!K2,IF($AM$1=2,'Komisyon Tarifeleri'!V2,'Komisyon Tarifeleri'!Q2),IF(AF2>='Komisyon Tarifeleri'!M2,IF($AM$1=2,'Komisyon Tarifeleri'!W2,'Komisyon Tarifeleri'!R2),IF($AM$1=2,'Komisyon Tarifeleri'!X2,'Komisyon Tarifeleri'!S2))))/100)-$D2-IF(AF2<=199.99,Kargo!$E$2,IF(AF2<=399.99,Kargo!$E$3,$F2))) | AH2: =IF(AG2="","",AG2/AF2) | AI2: =IF($D2="","",IF(Y2="","BUYBOX YOK → hedef kârla min fiyat",IF(AC2>=W2,"✓ BUYBOX ALTINA GİR","BUYBOX ALTI KÂRSIZ → min kârlı fiyat"))) | AJ2: =IF($B2="","",IFERROR(VLOOKUP($B2,Maliyetler!$A:$G,6,FALSE),"")) | AK2: =IF($B2="","",IFERROR(VLOOKUP($B2,Maliyetler!$A:$G,7,FALSE),"")) | AO2: =IF($B2="","",IFERROR(VLOOKUP($B2&"",'Plus Tarifeleri'!$C:$Q,11,FALSE),"")) | AP2: =IF(AO2="","",IFERROR(IF($AM$1=2,VLOOKUP($B2&"",'Plus Tarifeleri'!$C:$Q,15,FALSE),VLOOKUP($B2&"",'Plus Tarifeleri'!$C:$Q,13,FALSE)),"")) | AQ2: =IF(OR(AO2="",AP2="",$D2=""),"",AO2*(1-AP2/100)-$D2-IF(AO2<=199.99,Kargo!$E$2,IF(AO2<=399.99,Kargo!$E$3,$F2))) | AR2: =IF(AQ2="","",AQ2/AO2) | AS2: =IF(OR(AQ2="",AG2=""),"",AQ2-AG2)
A3: =IF('Komisyon Tarifeleri'!A3="","",'Komisyon Tarifeleri'!A3) | B3: =IF('Komisyon Tarifeleri'!B3="","",'Komisyon Tarifeleri'!B3&"") | C3: =IF($B3="","",'Komisyon Tarifeleri'!F3) | D3: =IF($B3="","",IFERROR(VLOOKUP($B3,Maliyetler!$A:$E,3,FALSE),"")) | E3: =IF($B3="","",IFERROR(VLOOKUP($B3,Maliyetler!$A:$E,4,FALSE),1)) | F3: =IF($B3="","",IFERROR(VLOOKUP(MIN(20,MAX(1,ROUND($E3,0))),Kargo!$A:$B,2,FALSE),99.46)) | G3: =IF($B3="","",IF(IF(N('Komisyon Tarifeleri'!AA3)>='Komisyon Tarifeleri'!I3,'Komisyon Tarifeleri'!AA3,'Komisyon Tarifeleri'!I3)="","",IF(N('Komisyon Tarifeleri'!AA3)>='Komisyon Tarifeleri'!I3,'Komisyon Tarifeleri'!AA3,'Komisyon Tarifeleri'!I3))) | H3: =IF(G3="","",IF($AM$1=2,'Komisyon Tarifeleri'!U3,'Komisyon Tarifeleri'!P3)) | I3: =IF(OR(G3="",$D3=""),"",G3*(1-H3/100)-$D3-IF(G3<=199.99,Kargo!$E$2,IF(G3<=399.99,Kargo!$E$3,$F3))) | J3: =IF(I3="","",I3/G3) | K3: =IF($B3="","",IF('Komisyon Tarifeleri'!J3="","",'Komisyon Tarifeleri'!J3)) | L3: =IF(K3="","",IF($AM$1=2,'Komisyon Tarifeleri'!V3,'Komisyon Tarifeleri'!Q3)) | M3: =IF(OR(K3="",$D3=""),"",K3*(1-L3/100)-$D3-IF(K3<=199.99,Kargo!$E$2,IF(K3<=399.99,Kargo!$E$3,$F3))) | N3: =IF(M3="","",M3/K3) | O3: =IF($B3="","",IF('Komisyon Tarifeleri'!L3="","",'Komisyon Tarifeleri'!L3)) | P3: =IF(O3="","",IF($AM$1=2,'Komisyon Tarifeleri'!W3,'Komisyon Tarifeleri'!R3)) | Q3: =IF(OR(O3="",$D3=""),"",O3*(1-P3/100)-$D3-IF(O3<=199.99,Kargo!$E$2,IF(O3<=399.99,Kargo!$E$3,$F3))) | R3: =IF(Q3="","",Q3/O3) | S3: =IF($B3="","",IF('Komisyon Tarifeleri'!N3="","",'Komisyon Tarifeleri'!N3)) | T3: =IF(S3="","",IF($AM$1=2,'Komisyon Tarifeleri'!X3,'Komisyon Tarifeleri'!S3)) | U3: =IF(OR(S3="",$D3=""),"",S3*(1-T3/100)-$D3-IF(S3<=199.99,Kargo!$E$2,IF(S3<=399.99,Kargo!$E$3,$F3))) | V3: =IF(U3="","",U3/S3) | W3: =IF($B3="","",IFERROR(VLOOKUP($C3,Hedefler!$A:$C,2,FALSE),0.04)) | X3: =IF($B3="","",IFERROR(VLOOKUP($C3,Hedefler!$A:$C,3,FALSE),0.1)) | Y3: =IF($B3="","",IFERROR(VLOOKUP($B3,Maliyetler!$A:$E,5,FALSE),"")) | Z3: =IF(OR(Y3="",Y3=0),"",Y3-1) | AA3: =IF(Z3="","",IF(Z3>='Komisyon Tarifeleri'!I3,IF($AM$1=2,'Komisyon Tarifeleri'!U3,'Komisyon Tarifeleri'!P3),IF(Z3>='Komisyon Tarifeleri'!K3,IF($AM$1=2,'Komisyon Tarifeleri'!V3,'Komisyon Tarifeleri'!Q3),IF(Z3>='Komisyon Tarifeleri'!M3,IF($AM$1=2,'Komisyon Tarifeleri'!W3,'Komisyon Tarifeleri'!R3),IF($AM$1=2,'Komisyon Tarifeleri'!X3,'Komisyon Tarifeleri'!S3))))) | AB3: =IF(OR(AA3="",$D3=""),"",Z3*(1-AA3/100)-$D3-IF(Z3<=199.99,Kargo!$E$2,IF(Z3<=399.99,Kargo!$E$3,$F3))) | AC3: =IF(AB3="","",AB3/Z3) | AD3: =IF(OR($D3="",$B3=""),"",IF(AND((1-T3/100-W3)>0,CEILING(($D3+$F3)/(1-T3/100-W3),1)<='Komisyon Tarifeleri'!N3),CEILING(($D3+$F3)/(1-T3/100-W3),1),IF(AND((1-P3/100-W3)>0,CEILING(MAX('Komisyon Tarifeleri'!M3,($D3+$F3)/(1-P3/100-W3)),1)<='Komisyon Tarifeleri'!L3),CEILING(MAX('Komisyon Tarifeleri'!M3,($D3+$F3)/(1-P3/100-W3)),1),IF(AND((1-L3/100-W3)>0,CEILING(MAX('Komisyon Tarifeleri'!K3,($D3+$F3)/(1-L3/100-W3)),1)<='Komisyon Tarifeleri'!J3),CEILING(MAX('Komisyon Tarifeleri'!K3,($D3+$F3)/(1-L3/100-W3)),1),IF((1-H3/100-W3)>0,CEILING(MAX('Komisyon Tarifeleri'!I3,($D3+$F3)/(1-H3/100-W3)),1),"İMKÂNSIZ"))))) | AE3: =IF(OR($D3="",$B3=""),"",IF(AND((1-T3/100-X3)>0,CEILING(($D3+$F3)/(1-T3/100-X3),1)<='Komisyon Tarifeleri'!N3),CEILING(($D3+$F3)/(1-T3/100-X3),1),IF(AND((1-P3/100-X3)>0,CEILING(MAX('Komisyon Tarifeleri'!M3,($D3+$F3)/(1-P3/100-X3)),1)<='Komisyon Tarifeleri'!L3),CEILING(MAX('Komisyon Tarifeleri'!M3,($D3+$F3)/(1-P3/100-X3)),1),IF(AND((1-L3/100-X3)>0,CEILING(MAX('Komisyon Tarifeleri'!K3,($D3+$F3)/(1-L3/100-X3)),1)<='Komisyon Tarifeleri'!J3),CEILING(MAX('Komisyon Tarifeleri'!K3,($D3+$F3)/(1-L3/100-X3)),1),IF((1-H3/100-X3)>0,CEILING(MAX('Komisyon Tarifeleri'!I3,($D3+$F3)/(1-H3/100-X3)),1),"İMKÂNSIZ"))))) | AF3: =IF($D3="","",IF(AND(Y3<>"",AC3<>"",AC3>=W3),Z3,IF(Y3<>"",AD3,AE3))) | AG3: =IF(OR(AF3="",AF3="İMKÂNSIZ"),"",AF3*(1-IF(AF3>='Komisyon Tarifeleri'!I3,IF($AM$1=2,'Komisyon Tarifeleri'!U3,'Komisyon Tarifeleri'!P3),IF(AF3>='Komisyon Tarifeleri'!K3,IF($AM$1=2,'Komisyon Tarifeleri'!V3,'Komisyon Tarifeleri'!Q3),IF(AF3>='Komisyon Tarifeleri'!M3,IF($AM$1=2,'Komisyon Tarifeleri'!W3,'Komisyon Tarifeleri'!R3),IF($AM$1=2,'Komisyon Tarifeleri'!X3,'Komisyon Tarifeleri'!S3))))/100)-$D3-IF(AF3<=199.99,Kargo!$E$2,IF(AF3<=399.99,Kargo!$E$3,$F3))) | AH3: =IF(AG3="","",AG3/AF3) | AI3: =IF($D3="","",IF(Y3="","BUYBOX YOK → hedef kârla min fiyat",IF(AC3>=W3,"✓ BUYBOX ALTINA GİR","BUYBOX ALTI KÂRSIZ → min kârlı fiyat"))) | AJ3: =IF($B3="","",IFERROR(VLOOKUP($B3,Maliyetler!$A:$G,6,FALSE),"")) | AK3: =IF($B3="","",IFERROR(VLOOKUP($B3,Maliyetler!$A:$G,7,FALSE),"")) | AO3: =IF($B3="","",IFERROR(VLOOKUP($B3&"",'Plus Tarifeleri'!$C:$Q,11,FALSE),"")) | AP3: =IF(AO3="","",IFERROR(IF($AM$1=2,VLOOKUP($B3&"",'Plus Tarifeleri'!$C:$Q,15,FALSE),VLOOKUP($B3&"",'Plus Tarifeleri'!$C:$Q,13,FALSE)),"")) | AQ3: =IF(OR(AO3="",AP3="",$D3=""),"",AO3*(1-AP3/100)-$D3-IF(AO3<=199.99,Kargo!$E$2,IF(AO3<=399.99,Kargo!$E$3,$F3))) | AR3: =IF(AQ3="","",AQ3/AO3) | AS3: =IF(OR(AQ3="",AG3=""),"",AQ3-AG3)
A4: =IF('Komisyon Tarifeleri'!A4="","",'Komisyon Tarifeleri'!A4) | B4: =IF('Komisyon Tarifeleri'!B4="","",'Komisyon Tarifeleri'!B4&"") | C4: =IF($B4="","",'Komisyon Tarifeleri'!F4) | D4: =IF($B4="","",IFERROR(VLOOKUP($B4,Maliyetler!$A:$E,3,FALSE),"")) | E4: =IF($B4="","",IFERROR(VLOOKUP($B4,Maliyetler!$A:$E,4,FALSE),1)) | F4: =IF($B4="","",IFERROR(VLOOKUP(MIN(20,MAX(1,ROUND($E4,0))),Kargo!$A:$B,2,FALSE),99.46)) | G4: =IF($B4="","",IF(IF(N('Komisyon Tarifeleri'!AA4)>='Komisyon Tarifeleri'!I4,'Komisyon Tarifeleri'!AA4,'Komisyon Tarifeleri'!I4)="","",IF(N('Komisyon Tarifeleri'!AA4)>='Komisyon Tarifeleri'!I4,'Komisyon Tarifeleri'!AA4,'Komisyon Tarifeleri'!I4))) | H4: =IF(G4="","",IF($AM$1=2,'Komisyon Tarifeleri'!U4,'Komisyon Tarifeleri'!P4)) | I4: =IF(OR(G4="",$D4=""),"",G4*(1-H4/100)-$D4-IF(G4<=199.99,Kargo!$E$2,IF(G4<=399.99,Kargo!$E$3,$F4))) | J4: =IF(I4="","",I4/G4) | K4: =IF($B4="","",IF('Komisyon Tarifeleri'!J4="","",'Komisyon Tarifeleri'!J4)) | L4: =IF(K4="","",IF($AM$1=2,'Komisyon Tarifeleri'!V4,'Komisyon Tarifeleri'!Q4)) | M4: =IF(OR(K4="",$D4=""),"",K4*(1-L4/100)-$D4-IF(K4<=199.99,Kargo!$E$2,IF(K4<=399.99,Kargo!$E$3,$F4))) | N4: =IF(M4="","",M4/K4) | O4: =IF($B4="","",IF('Komisyon Tarifeleri'!L4="","",'Komisyon Tarifeleri'!L4)) | P4: =IF(O4="","",IF($AM$1=2,'Komisyon Tarifeleri'!W4,'Komisyon Tarifeleri'!R4)) | Q4: =IF(OR(O4="",$D4=""),"",O4*(1-P4/100)-$D4-IF(O4<=199.99,Kargo!$E$2,IF(O4<=399.99,Kargo!$E$3,$F4))) | R4: =IF(Q4="","",Q4/O4) | S4: =IF($B4="","",IF('Komisyon Tarifeleri'!N4="","",'Komisyon Tarifeleri'!N4)) | T4: =IF(S4="","",IF($AM$1=2,'Komisyon Tarifeleri'!X4,'Komisyon Tarifeleri'!S4)) | U4: =IF(OR(S4="",$D4=""),"",S4*(1-T4/100)-$D4-IF(S4<=199.99,Kargo!$E$2,IF(S4<=399.99,Kargo!$E$3,$F4))) | V4: =IF(U4="","",U4/S4) | W4: =IF($B4="","",IFERROR(VLOOKUP($C4,Hedefler!$A:$C,2,FALSE),0.04)) | X4: =IF($B4="","",IFERROR(VLOOKUP($C4,Hedefler!$A:$C,3,FALSE),0.1)) | Y4: =IF($B4="","",IFERROR(VLOOKUP($B4,Maliyetler!$A:$E,5,FALSE),"")) | Z4: =IF(OR(Y4="",Y4=0),"",Y4-1) | AA4: =IF(Z4="","",IF(Z4>='Komisyon Tarifeleri'!I4,IF($AM$1=2,'Komisyon Tarifeleri'!U4,'Komisyon Tarifeleri'!P4),IF(Z4>='Komisyon Tarifeleri'!K4,IF($AM$1=2,'Komisyon Tarifeleri'!V4,'Komisyon Tarifeleri'!Q4),IF(Z4>='Komisyon Tarifeleri'!M4,IF($AM$1=2,'Komisyon Tarifeleri'!W4,'Komisyon Tarifeleri'!R4),IF($AM$1=2,'Komisyon Tarifeleri'!X4,'Komisyon Tarifeleri'!S4))))) | AB4: =IF(OR(AA4="",$D4=""),"",Z4*(1-AA4/100)-$D4-IF(Z4<=199.99,Kargo!$E$2,IF(Z4<=399.99,Kargo!$E$3,$F4))) | AC4: =IF(AB4="","",AB4/Z4) | AD4: =IF(OR($D4="",$B4=""),"",IF(AND((1-T4/100-W4)>0,CEILING(($D4+$F4)/(1-T4/100-W4),1)<='Komisyon Tarifeleri'!N4),CEILING(($D4+$F4)/(1-T4/100-W4),1),IF(AND((1-P4/100-W4)>0,CEILING(MAX('Komisyon Tarifeleri'!M4,($D4+$F4)/(1-P4/100-W4)),1)<='Komisyon Tarifeleri'!L4),CEILING(MAX('Komisyon Tarifeleri'!M4,($D4+$F4)/(1-P4/100-W4)),1),IF(AND((1-L4/100-W4)>0,CEILING(MAX('Komisyon Tarifeleri'!K4,($D4+$F4)/(1-L4/100-W4)),1)<='Komisyon Tarifeleri'!J4),CEILING(MAX('Komisyon Tarifeleri'!K4,($D4+$F4)/(1-L4/100-W4)),1),IF((1-H4/100-W4)>0,CEILING(MAX('Komisyon Tarifeleri'!I4,($D4+$F4)/(1-H4/100-W4)),1),"İMKÂNSIZ"))))) | AE4: =IF(OR($D4="",$B4=""),"",IF(AND((1-T4/100-X4)>0,CEILING(($D4+$F4)/(1-T4/100-X4),1)<='Komisyon Tarifeleri'!N4),CEILING(($D4+$F4)/(1-T4/100-X4),1),IF(AND((1-P4/100-X4)>0,CEILING(MAX('Komisyon Tarifeleri'!M4,($D4+$F4)/(1-P4/100-X4)),1)<='Komisyon Tarifeleri'!L4),CEILING(MAX('Komisyon Tarifeleri'!M4,($D4+$F4)/(1-P4/100-X4)),1),IF(AND((1-L4/100-X4)>0,CEILING(MAX('Komisyon Tarifeleri'!K4,($D4+$F4)/(1-L4/100-X4)),1)<='Komisyon Tarifeleri'!J4),CEILING(MAX('Komisyon Tarifeleri'!K4,($D4+$F4)/(1-L4/100-X4)),1),IF((1-H4/100-X4)>0,CEILING(MAX('Komisyon Tarifeleri'!I4,($D4+$F4)/(1-H4/100-X4)),1),"İMKÂNSIZ"))))) | AF4: =IF($D4="","",IF(AND(Y4<>"",AC4<>"",AC4>=W4),Z4,IF(Y4<>"",AD4,AE4))) | AG4: =IF(OR(AF4="",AF4="İMKÂNSIZ"),"",AF4*(1-IF(AF4>='Komisyon Tarifeleri'!I4,IF($AM$1=2,'Komisyon Tarifeleri'!U4,'Komisyon Tarifeleri'!P4),IF(AF4>='Komisyon Tarifeleri'!K4,IF($AM$1=2,'Komisyon Tarifeleri'!V4,'Komisyon Tarifeleri'!Q4),IF(AF4>='Komisyon Tarifeleri'!M4,IF($AM$1=2,'Komisyon Tarifeleri'!W4,'Komisyon Tarifeleri'!R4),IF($AM$1=2,'Komisyon Tarifeleri'!X4,'Komisyon Tarifeleri'!S4))))/100)-$D4-IF(AF4<=199.99,Kargo!$E$2,IF(AF4<=399.99,Kargo!$E$3,$F4))) | AH4: =IF(AG4="","",AG4/AF4) | AI4: =IF($D4="","",IF(Y4="","BUYBOX YOK → hedef kârla min fiyat",IF(AC4>=W4,"✓ BUYBOX ALTINA GİR","BUYBOX ALTI KÂRSIZ → min kârlı fiyat"))) | AJ4: =IF($B4="","",IFERROR(VLOOKUP($B4,Maliyetler!$A:$G,6,FALSE),"")) | AK4: =IF($B4="","",IFERROR(VLOOKUP($B4,Maliyetler!$A:$G,7,FALSE),"")) | AO4: =IF($B4="","",IFERROR(VLOOKUP($B4&"",'Plus Tarifeleri'!$C:$Q,11,FALSE),"")) | AP4: =IF(AO4="","",IFERROR(IF($AM$1=2,VLOOKUP($B4&"",'Plus Tarifeleri'!$C:$Q,15,FALSE),VLOOKUP($B4&"",'Plus Tarifeleri'!$C:$Q,13,FALSE)),"")) | AQ4: =IF(OR(AO4="",AP4="",$D4=""),"",AO4*(1-AP4/100)-$D4-IF(AO4<=199.99,Kargo!$E$2,IF(AO4<=399.99,Kargo!$E$3,$F4))) | AR4: =IF(AQ4="","",AQ4/AO4) | AS4: =IF(OR(AQ4="",AG4=""),"",AQ4-AG4)
A5: =IF('Komisyon Tarifeleri'!A5="","",'Komisyon Tarifeleri'!A5) | B5: =IF('Komisyon Tarifeleri'!B5="","",'Komisyon Tarifeleri'!B5&"") | C5: =IF($B5="","",'Komisyon Tarifeleri'!F5) | D5: =IF($B5="","",IFERROR(VLOOKUP($B5,Maliyetler!$A:$E,3,FALSE),"")) | E5: =IF($B5="","",IFERROR(VLOOKUP($B5,Maliyetler!$A:$E,4,FALSE),1)) | F5: =IF($B5="","",IFERROR(VLOOKUP(MIN(20,MAX(1,ROUND($E5,0))),Kargo!$A:$B,2,FALSE),99.46)) | G5: =IF($B5="","",IF(IF(N('Komisyon Tarifeleri'!AA5)>='Komisyon Tarifeleri'!I5,'Komisyon Tarifeleri'!AA5,'Komisyon Tarifeleri'!I5)="","",IF(N('Komisyon Tarifeleri'!AA5)>='Komisyon Tarifeleri'!I5,'Komisyon Tarifeleri'!AA5,'Komisyon Tarifeleri'!I5))) | H5: =IF(G5="","",IF($AM$1=2,'Komisyon Tarifeleri'!U5,'Komisyon Tarifeleri'!P5)) | I5: =IF(OR(G5="",$D5=""),"",G5*(1-H5/100)-$D5-IF(G5<=199.99,Kargo!$E$2,IF(G5<=399.99,Kargo!$E$3,$F5))) | J5: =IF(I5="","",I5/G5) | K5: =IF($B5="","",IF('Komisyon Tarifeleri'!J5="","",'Komisyon Tarifeleri'!J5)) | L5: =IF(K5="","",IF($AM$1=2,'Komisyon Tarifeleri'!V5,'Komisyon Tarifeleri'!Q5)) | M5: =IF(OR(K5="",$D5=""),"",K5*(1-L5/100)-$D5-IF(K5<=199.99,Kargo!$E$2,IF(K5<=399.99,Kargo!$E$3,$F5))) | N5: =IF(M5="","",M5/K5) | O5: =IF($B5="","",IF('Komisyon Tarifeleri'!L5="","",'Komisyon Tarifeleri'!L5)) | P5: =IF(O5="","",IF($AM$1=2,'Komisyon Tarifeleri'!W5,'Komisyon Tarifeleri'!R5)) | Q5: =IF(OR(O5="",$D5=""),"",O5*(1-P5/100)-$D5-IF(O5<=199.99,Kargo!$E$2,IF(O5<=399.99,Kargo!$E$3,$F5))) | R5: =IF(Q5="","",Q5/O5) | S5: =IF($B5="","",IF('Komisyon Tarifeleri'!N5="","",'Komisyon Tarifeleri'!N5)) | T5: =IF(S5="","",IF($AM$1=2,'Komisyon Tarifeleri'!X5,'Komisyon Tarifeleri'!S5)) | U5: =IF(OR(S5="",$D5=""),"",S5*(1-T5/100)-$D5-IF(S5<=199.99,Kargo!$E$2,IF(S5<=399.99,Kargo!$E$3,$F5))) | V5: =IF(U5="","",U5/S5) | W5: =IF($B5="","",IFERROR(VLOOKUP($C5,Hedefler!$A:$C,2,FALSE),0.04)) | X5: =IF($B5="","",IFERROR(VLOOKUP($C5,Hedefler!$A:$C,3,FALSE),0.1)) | Y5: =IF($B5="","",IFERROR(VLOOKUP($B5,Maliyetler!$A:$E,5,FALSE),"")) | Z5: =IF(OR(Y5="",Y5=0),"",Y5-1) | AA5: =IF(Z5="","",IF(Z5>='Komisyon Tarifeleri'!I5,IF($AM$1=2,'Komisyon Tarifeleri'!U5,'Komisyon Tarifeleri'!P5),IF(Z5>='Komisyon Tarifeleri'!K5,IF($AM$1=2,'Komisyon Tarifeleri'!V5,'Komisyon Tarifeleri'!Q5),IF(Z5>='Komisyon Tarifeleri'!M5,IF($AM$1=2,'Komisyon Tarifeleri'!W5,'Komisyon Tarifeleri'!R5),IF($AM$1=2,'Komisyon Tarifeleri'!X5,'Komisyon Tarifeleri'!S5))))) | AB5: =IF(OR(AA5="",$D5=""),"",Z5*(1-AA5/100)-$D5-IF(Z5<=199.99,Kargo!$E$2,IF(Z5<=399.99,Kargo!$E$3,$F5))) | AC5: =IF(AB5="","",AB5/Z5) | AD5: =IF(OR($D5="",$B5=""),"",IF(AND((1-T5/100-W5)>0,CEILING(($D5+$F5)/(1-T5/100-W5),1)<='Komisyon Tarifeleri'!N5),CEILING(($D5+$F5)/(1-T5/100-W5),1),IF(AND((1-P5/100-W5)>0,CEILING(MAX('Komisyon Tarifeleri'!M5,($D5+$F5)/(1-P5/100-W5)),1)<='Komisyon Tarifeleri'!L5),CEILING(MAX('Komisyon Tarifeleri'!M5,($D5+$F5)/(1-P5/100-W5)),1),IF(AND((1-L5/100-W5)>0,CEILING(MAX('Komisyon Tarifeleri'!K5,($D5+$F5)/(1-L5/100-W5)),1)<='Komisyon Tarifeleri'!J5),CEILING(MAX('Komisyon Tarifeleri'!K5,($D5+$F5)/(1-L5/100-W5)),1),IF((1-H5/100-W5)>0,CEILING(MAX('Komisyon Tarifeleri'!I5,($D5+$F5)/(1-H5/100-W5)),1),"İMKÂNSIZ"))))) | AE5: =IF(OR($D5="",$B5=""),"",IF(AND((1-T5/100-X5)>0,CEILING(($D5+$F5)/(1-T5/100-X5),1)<='Komisyon Tarifeleri'!N5),CEILING(($D5+$F5)/(1-T5/100-X5),1),IF(AND((1-P5/100-X5)>0,CEILING(MAX('Komisyon Tarifeleri'!M5,($D5+$F5)/(1-P5/100-X5)),1)<='Komisyon Tarifeleri'!L5),CEILING(MAX('Komisyon Tarifeleri'!M5,($D5+$F5)/(1-P5/100-X5)),1),IF(AND((1-L5/100-X5)>0,CEILING(MAX('Komisyon Tarifeleri'!K5,($D5+$F5)/(1-L5/100-X5)),1)<='Komisyon Tarifeleri'!J5),CEILING(MAX('Komisyon Tarifeleri'!K5,($D5+$F5)/(1-L5/100-X5)),1),IF((1-H5/100-X5)>0,CEILING(MAX('Komisyon Tarifeleri'!I5,($D5+$F5)/(1-H5/100-X5)),1),"İMKÂNSIZ"))))) | AF5: =IF($D5="","",IF(AND(Y5<>"",AC5<>"",AC5>=W5),Z5,IF(Y5<>"",AD5,AE5))) | AG5: =IF(OR(AF5="",AF5="İMKÂNSIZ"),"",AF5*(1-IF(AF5>='Komisyon Tarifeleri'!I5,IF($AM$1=2,'Komisyon Tarifeleri'!U5,'Komisyon Tarifeleri'!P5),IF(AF5>='Komisyon Tarifeleri'!K5,IF($AM$1=2,'Komisyon Tarifeleri'!V5,'Komisyon Tarifeleri'!Q5),IF(AF5>='Komisyon Tarifeleri'!M5,IF($AM$1=2,'Komisyon Tarifeleri'!W5,'Komisyon Tarifeleri'!R5),IF($AM$1=2,'Komisyon Tarifeleri'!X5,'Komisyon Tarifeleri'!S5))))/100)-$D5-IF(AF5<=199.99,Kargo!$E$2,IF(AF5<=399.99,Kargo!$E$3,$F5))) | AH5: =IF(AG5="","",AG5/AF5) | AI5: =IF($D5="","",IF(Y5="","BUYBOX YOK → hedef kârla min fiyat",IF(AC5>=W5,"✓ BUYBOX ALTINA GİR","BUYBOX ALTI KÂRSIZ → min kârlı fiyat"))) | AJ5: =IF($B5="","",IFERROR(VLOOKUP($B5,Maliyetler!$A:$G,6,FALSE),"")) | AK5: =IF($B5="","",IFERROR(VLOOKUP($B5,Maliyetler!$A:$G,7,FALSE),"")) | AO5: =IF($B5="","",IFERROR(VLOOKUP($B5&"",'Plus Tarifeleri'!$C:$Q,11,FALSE),"")) | AP5: =IF(AO5="","",IFERROR(IF($AM$1=2,VLOOKUP($B5&"",'Plus Tarifeleri'!$C:$Q,15,FALSE),VLOOKUP($B5&"",'Plus Tarifeleri'!$C:$Q,13,FALSE)),"")) | AQ5: =IF(OR(AO5="",AP5="",$D5=""),"",AO5*(1-AP5/100)-$D5-IF(AO5<=199.99,Kargo!$E$2,IF(AO5<=399.99,Kargo!$E$3,$F5))) | AR5: =IF(AQ5="","",AQ5/AO5) | AS5: =IF(OR(AQ5="",AG5=""),"",AQ5-AG5)
A6: =IF('Komisyon Tarifeleri'!A6="","",'Komisyon Tarifeleri'!A6) | B6: =IF('Komisyon Tarifeleri'!B6="","",'Komisyon Tarifeleri'!B6&"") | C6: =IF($B6="","",'Komisyon Tarifeleri'!F6) | D6: =IF($B6="","",IFERROR(VLOOKUP($B6,Maliyetler!$A:$E,3,FALSE),"")) | E6: =IF($B6="","",IFERROR(VLOOKUP($B6,Maliyetler!$A:$E,4,FALSE),1)) | F6: =IF($B6="","",IFERROR(VLOOKUP(MIN(20,MAX(1,ROUND($E6,0))),Kargo!$A:$B,2,FALSE),99.46)) | G6: =IF($B6="","",IF(IF(N('Komisyon Tarifeleri'!AA6)>='Komisyon Tarifeleri'!I6,'Komisyon Tarifeleri'!AA6,'Komisyon Tarifeleri'!I6)="","",IF(N('Komisyon Tarifeleri'!AA6)>='Komisyon Tarifeleri'!I6,'Komisyon Tarifeleri'!AA6,'Komisyon Tarifeleri'!I6))) | H6: =IF(G6="","",IF($AM$1=2,'Komisyon Tarifeleri'!U6,'Komisyon Tarifeleri'!P6)) | I6: =IF(OR(G6="",$D6=""),"",G6*(1-H6/100)-$D6-IF(G6<=199.99,Kargo!$E$2,IF(G6<=399.99,Kargo!$E$3,$F6))) | J6: =IF(I6="","",I6/G6) | K6: =IF($B6="","",IF('Komisyon Tarifeleri'!J6="","",'Komisyon Tarifeleri'!J6)) | L6: =IF(K6="","",IF($AM$1=2,'Komisyon Tarifeleri'!V6,'Komisyon Tarifeleri'!Q6)) | M6: =IF(OR(K6="",$D6=""),"",K6*(1-L6/100)-$D6-IF(K6<=199.99,Kargo!$E$2,IF(K6<=399.99,Kargo!$E$3,$F6))) | N6: =IF(M6="","",M6/K6) | O6: =IF($B6="","",IF('Komisyon Tarifeleri'!L6="","",'Komisyon Tarifeleri'!L6)) | P6: =IF(O6="","",IF($AM$1=2,'Komisyon Tarifeleri'!W6,'Komisyon Tarifeleri'!R6)) | Q6: =IF(OR(O6="",$D6=""),"",O6*(1-P6/100)-$D6-IF(O6<=199.99,Kargo!$E$2,IF(O6<=399.99,Kargo!$E$3,$F6))) | R6: =IF(Q6="","",Q6/O6) | S6: =IF($B6="","",IF('Komisyon Tarifeleri'!N6="","",'Komisyon Tarifeleri'!N6)) | T6: =IF(S6="","",IF($AM$1=2,'Komisyon Tarifeleri'!X6,'Komisyon Tarifeleri'!S6)) | U6: =IF(OR(S6="",$D6=""),"",S6*(1-T6/100)-$D6-IF(S6<=199.99,Kargo!$E$2,IF(S6<=399.99,Kargo!$E$3,$F6))) | V6: =IF(U6="","",U6/S6) | W6: =IF($B6="","",IFERROR(VLOOKUP($C6,Hedefler!$A:$C,2,FALSE),0.04)) | X6: =IF($B6="","",IFERROR(VLOOKUP($C6,Hedefler!$A:$C,3,FALSE),0.1)) | Y6: =IF($B6="","",IFERROR(VLOOKUP($B6,Maliyetler!$A:$E,5,FALSE),"")) | Z6: =IF(OR(Y6="",Y6=0),"",Y6-1) | AA6: =IF(Z6="","",IF(Z6>='Komisyon Tarifeleri'!I6,IF($AM$1=2,'Komisyon Tarifeleri'!U6,'Komisyon Tarifeleri'!P6),IF(Z6>='Komisyon Tarifeleri'!K6,IF($AM$1=2,'Komisyon Tarifeleri'!V6,'Komisyon Tarifeleri'!Q6),IF(Z6>='Komisyon Tarifeleri'!M6,IF($AM$1=2,'Komisyon Tarifeleri'!W6,'Komisyon Tarifeleri'!R6),IF($AM$1=2,'Komisyon Tarifeleri'!X6,'Komisyon Tarifeleri'!S6))))) | AB6: =IF(OR(AA6="",$D6=""),"",Z6*(1-AA6/100)-$D6-IF(Z6<=199.99,Kargo!$E$2,IF(Z6<=399.99,Kargo!$E$3,$F6))) | AC6: =IF(AB6="","",AB6/Z6) | AD6: =IF(OR($D6="",$B6=""),"",IF(AND((1-T6/100-W6)>0,CEILING(($D6+$F6)/(1-T6/100-W6),1)<='Komisyon Tarifeleri'!N6),CEILING(($D6+$F6)/(1-T6/100-W6),1),IF(AND((1-P6/100-W6)>0,CEILING(MAX('Komisyon Tarifeleri'!M6,($D6+$F6)/(1-P6/100-W6)),1)<='Komisyon Tarifeleri'!L6),CEILING(MAX('Komisyon Tarifeleri'!M6,($D6+$F6)/(1-P6/100-W6)),1),IF(AND((1-L6/100-W6)>0,CEILING(MAX('Komisyon Tarifeleri'!K6,($D6+$F6)/(1-L6/100-W6)),1)<='Komisyon Tarifeleri'!J6),CEILING(MAX('Komisyon Tarifeleri'!K6,($D6+$F6)/(1-L6/100-W6)),1),IF((1-H6/100-W6)>0,CEILING(MAX('Komisyon Tarifeleri'!I6,($D6+$F6)/(1-H6/100-W6)),1),"İMKÂNSIZ"))))) | AE6: =IF(OR($D6="",$B6=""),"",IF(AND((1-T6/100-X6)>0,CEILING(($D6+$F6)/(1-T6/100-X6),1)<='Komisyon Tarifeleri'!N6),CEILING(($D6+$F6)/(1-T6/100-X6),1),IF(AND((1-P6/100-X6)>0,CEILING(MAX('Komisyon Tarifeleri'!M6,($D6+$F6)/(1-P6/100-X6)),1)<='Komisyon Tarifeleri'!L6),CEILING(MAX('Komisyon Tarifeleri'!M6,($D6+$F6)/(1-P6/100-X6)),1),IF(AND((1-L6/100-X6)>0,CEILING(MAX('Komisyon Tarifeleri'!K6,($D6+$F6)/(1-L6/100-X6)),1)<='Komisyon Tarifeleri'!J6),CEILING(MAX('Komisyon Tarifeleri'!K6,($D6+$F6)/(1-L6/100-X6)),1),IF((1-H6/100-X6)>0,CEILING(MAX('Komisyon Tarifeleri'!I6,($D6+$F6)/(1-H6/100-X6)),1),"İMKÂNSIZ"))))) | AF6: =IF($D6="","",IF(AND(Y6<>"",AC6<>"",AC6>=W6),Z6,IF(Y6<>"",AD6,AE6))) | AG6: =IF(OR(AF6="",AF6="İMKÂNSIZ"),"",AF6*(1-IF(AF6>='Komisyon Tarifeleri'!I6,IF($AM$1=2,'Komisyon Tarifeleri'!U6,'Komisyon Tarifeleri'!P6),IF(AF6>='Komisyon Tarifeleri'!K6,IF($AM$1=2,'Komisyon Tarifeleri'!V6,'Komisyon Tarifeleri'!Q6),IF(AF6>='Komisyon Tarifeleri'!M6,IF($AM$1=2,'Komisyon Tarifeleri'!W6,'Komisyon Tarifeleri'!R6),IF($AM$1=2,'Komisyon Tarifeleri'!X6,'Komisyon Tarifeleri'!S6))))/100)-$D6-IF(AF6<=199.99,Kargo!$E$2,IF(AF6<=399.99,Kargo!$E$3,$F6))) | AH6: =IF(AG6="","",AG6/AF6) | AI6: =IF($D6="","",IF(Y6="","BUYBOX YOK → hedef kârla min fiyat",IF(AC6>=W6,"✓ BUYBOX ALTINA GİR","BUYBOX ALTI KÂRSIZ → min kârlı fiyat"))) | AJ6: =IF($B6="","",IFERROR(VLOOKUP($B6,Maliyetler!$A:$G,6,FALSE),"")) | AK6: =IF($B6="","",IFERROR(VLOOKUP($B6,Maliyetler!$A:$G,7,FALSE),"")) | AO6: =IF($B6="","",IFERROR(VLOOKUP($B6&"",'Plus Tarifeleri'!$C:$Q,11,FALSE),"")) | AP6: =IF(AO6="","",IFERROR(IF($AM$1=2,VLOOKUP($B6&"",'Plus Tarifeleri'!$C:$Q,15,FALSE),VLOOKUP($B6&"",'Plus Tarifeleri'!$C:$Q,13,FALSE)),"")) | AQ6: =IF(OR(AO6="",AP6="",$D6=""),"",AO6*(1-AP6/100)-$D6-IF(AO6<=199.99,Kargo!$E$2,IF(AO6<=399.99,Kargo!$E$3,$F6))) | AR6: =IF(AQ6="","",AQ6/AO6) | AS6: =IF(OR(AQ6="",AG6=""),"",AQ6-AG6)
A7: =IF('Komisyon Tarifeleri'!A7="","",'Komisyon Tarifeleri'!A7) | B7: =IF('Komisyon Tarifeleri'!B7="","",'Komisyon Tarifeleri'!B7&"") | C7: =IF($B7="","",'Komisyon Tarifeleri'!F7) | D7: =IF($B7="","",IFERROR(VLOOKUP($B7,Maliyetler!$A:$E,3,FALSE),"")) | E7: =IF($B7="","",IFERROR(VLOOKUP($B7,Maliyetler!$A:$E,4,FALSE),1)) | F7: =IF($B7="","",IFERROR(VLOOKUP(MIN(20,MAX(1,ROUND($E7,0))),Kargo!$A:$B,2,FALSE),99.46)) | G7: =IF($B7="","",IF(IF(N('Komisyon Tarifeleri'!AA7)>='Komisyon Tarifeleri'!I7,'Komisyon Tarifeleri'!AA7,'Komisyon Tarifeleri'!I7)="","",IF(N('Komisyon Tarifeleri'!AA7)>='Komisyon Tarifeleri'!I7,'Komisyon Tarifeleri'!AA7,'Komisyon Tarifeleri'!I7))) | H7: =IF(G7="","",IF($AM$1=2,'Komisyon Tarifeleri'!U7,'Komisyon Tarifeleri'!P7)) | I7: =IF(OR(G7="",$D7=""),"",G7*(1-H7/100)-$D7-IF(G7<=199.99,Kargo!$E$2,IF(G7<=399.99,Kargo!$E$3,$F7))) | J7: =IF(I7="","",I7/G7) | K7: =IF($B7="","",IF('Komisyon Tarifeleri'!J7="","",'Komisyon Tarifeleri'!J7)) | L7: =IF(K7="","",IF($AM$1=2,'Komisyon Tarifeleri'!V7,'Komisyon Tarifeleri'!Q7)) | M7: =IF(OR(K7="",$D7=""),"",K7*(1-L7/100)-$D7-IF(K7<=199.99,Kargo!$E$2,IF(K7<=399.99,Kargo!$E$3,$F7))) | N7: =IF(M7="","",M7/K7) | O7: =IF($B7="","",IF('Komisyon Tarifeleri'!L7="","",'Komisyon Tarifeleri'!L7)) | P7: =IF(O7="","",IF($AM$1=2,'Komisyon Tarifeleri'!W7,'Komisyon Tarifeleri'!R7)) | Q7: =IF(OR(O7="",$D7=""),"",O7*(1-P7/100)-$D7-IF(O7<=199.99,Kargo!$E$2,IF(O7<=399.99,Kargo!$E$3,$F7))) | R7: =IF(Q7="","",Q7/O7) | S7: =IF($B7="","",IF('Komisyon Tarifeleri'!N7="","",'Komisyon Tarifeleri'!N7)) | T7: =IF(S7="","",IF($AM$1=2,'Komisyon Tarifeleri'!X7,'Komisyon Tarifeleri'!S7)) | U7: =IF(OR(S7="",$D7=""),"",S7*(1-T7/100)-$D7-IF(S7<=199.99,Kargo!$E$2,IF(S7<=399.99,Kargo!$E$3,$F7))) | V7: =IF(U7="","",U7/S7) | W7: =IF($B7="","",IFERROR(VLOOKUP($C7,Hedefler!$A:$C,2,FALSE),0.04)) | X7: =IF($B7="","",IFERROR(VLOOKUP($C7,Hedefler!$A:$C,3,FALSE),0.1)) | Y7: =IF($B7="","",IFERROR(VLOOKUP($B7,Maliyetler!$A:$E,5,FALSE),"")) | Z7: =IF(OR(Y7="",Y7=0),"",Y7-1) | AA7: =IF(Z7="","",IF(Z7>='Komisyon Tarifeleri'!I7,IF($AM$1=2,'Komisyon Tarifeleri'!U7,'Komisyon Tarifeleri'!P7),IF(Z7>='Komisyon Tarifeleri'!K7,IF($AM$1=2,'Komisyon Tarifeleri'!V7,'Komisyon Tarifeleri'!Q7),IF(Z7>='Komisyon Tarifeleri'!M7,IF($AM$1=2,'Komisyon Tarifeleri'!W7,'Komisyon Tarifeleri'!R7),IF($AM$1=2,'Komisyon Tarifeleri'!X7,'Komisyon Tarifeleri'!S7))))) | AB7: =IF(OR(AA7="",$D7=""),"",Z7*(1-AA7/100)-$D7-IF(Z7<=199.99,Kargo!$E$2,IF(Z7<=399.99,Kargo!$E$3,$F7))) | AC7: =IF(AB7="","",AB7/Z7) | AD7: =IF(OR($D7="",$B7=""),"",IF(AND((1-T7/100-W7)>0,CEILING(($D7+$F7)/(1-T7/100-W7),1)<='Komisyon Tarifeleri'!N7),CEILING(($D7+$F7)/(1-T7/100-W7),1),IF(AND((1-P7/100-W7)>0,CEILING(MAX('Komisyon Tarifeleri'!M7,($D7+$F7)/(1-P7/100-W7)),1)<='Komisyon Tarifeleri'!L7),CEILING(MAX('Komisyon Tarifeleri'!M7,($D7+$F7)/(1-P7/100-W7)),1),IF(AND((1-L7/100-W7)>0,CEILING(MAX('Komisyon Tarifeleri'!K7,($D7+$F7)/(1-L7/100-W7)),1)<='Komisyon Tarifeleri'!J7),CEILING(MAX('Komisyon Tarifeleri'!K7,($D7+$F7)/(1-L7/100-W7)),1),IF((1-H7/100-W7)>0,CEILING(MAX('Komisyon Tarifeleri'!I7,($D7+$F7)/(1-H7/100-W7)),1),"İMKÂNSIZ"))))) | AE7: =IF(OR($D7="",$B7=""),"",IF(AND((1-T7/100-X7)>0,CEILING(($D7+$F7)/(1-T7/100-X7),1)<='Komisyon Tarifeleri'!N7),CEILING(($D7+$F7)/(1-T7/100-X7),1),IF(AND((1-P7/100-X7)>0,CEILING(MAX('Komisyon Tarifeleri'!M7,($D7+$F7)/(1-P7/100-X7)),1)<='Komisyon Tarifeleri'!L7),CEILING(MAX('Komisyon Tarifeleri'!M7,($D7+$F7)/(1-P7/100-X7)),1),IF(AND((1-L7/100-X7)>0,CEILING(MAX('Komisyon Tarifeleri'!K7,($D7+$F7)/(1-L7/100-X7)),1)<='Komisyon Tarifeleri'!J7),CEILING(MAX('Komisyon Tarifeleri'!K7,($D7+$F7)/(1-L7/100-X7)),1),IF((1-H7/100-X7)>0,CEILING(MAX('Komisyon Tarifeleri'!I7,($D7+$F7)/(1-H7/100-X7)),1),"İMKÂNSIZ"))))) | AF7: =IF($D7="","",IF(AND(Y7<>"",AC7<>"",AC7>=W7),Z7,IF(Y7<>"",AD7,AE7))) | AG7: =IF(OR(AF7="",AF7="İMKÂNSIZ"),"",AF7*(1-IF(AF7>='Komisyon Tarifeleri'!I7,IF($AM$1=2,'Komisyon Tarifeleri'!U7,'Komisyon Tarifeleri'!P7),IF(AF7>='Komisyon Tarifeleri'!K7,IF($AM$1=2,'Komisyon Tarifeleri'!V7,'Komisyon Tarifeleri'!Q7),IF(AF7>='Komisyon Tarifeleri'!M7,IF($AM$1=2,'Komisyon Tarifeleri'!W7,'Komisyon Tarifeleri'!R7),IF($AM$1=2,'Komisyon Tarifeleri'!X7,'Komisyon Tarifeleri'!S7))))/100)-$D7-IF(AF7<=199.99,Kargo!$E$2,IF(AF7<=399.99,Kargo!$E$3,$F7))) | AH7: =IF(AG7="","",AG7/AF7) | AI7: =IF($D7="","",IF(Y7="","BUYBOX YOK → hedef kârla min fiyat",IF(AC7>=W7,"✓ BUYBOX ALTINA GİR","BUYBOX ALTI KÂRSIZ → min kârlı fiyat"))) | AJ7: =IF($B7="","",IFERROR(VLOOKUP($B7,Maliyetler!$A:$G,6,FALSE),"")) | AK7: =IF($B7="","",IFERROR(VLOOKUP($B7,Maliyetler!$A:$G,7,FALSE),"")) | AO7: =IF($B7="","",IFERROR(VLOOKUP($B7&"",'Plus Tarifeleri'!$C:$Q,11,FALSE),"")) | AP7: =IF(AO7="","",IFERROR(IF($AM$1=2,VLOOKUP($B7&"",'Plus Tarifeleri'!$C:$Q,15,FALSE),VLOOKUP($B7&"",'Plus Tarifeleri'!$C:$Q,13,FALSE)),"")) | AQ7: =IF(OR(AO7="",AP7="",$D7=""),"",AO7*(1-AP7/100)-$D7-IF(AO7<=199.99,Kargo!$E$2,IF(AO7<=399.99,Kargo!$E$3,$F7))) | AR7: =IF(AQ7="","",AQ7/AO7) | AS7: =IF(OR(AQ7="",AG7=""),"",AQ7-AG7)
A8: =IF('Komisyon Tarifeleri'!A8="","",'Komisyon Tarifeleri'!A8) | B8: =IF('Komisyon Tarifeleri'!B8="","",'Komisyon Tarifeleri'!B8&"") | C8: =IF($B8="","",'Komisyon Tarifeleri'!F8) | D8: =IF($B8="","",IFERROR(VLOOKUP($B8,Maliyetler!$A:$E,3,FALSE),"")) | E8: =IF($B8="","",IFERROR(VLOOKUP($B8,Maliyetler!$A:$E,4,FALSE),1)) | F8: =IF($B8="","",IFERROR(VLOOKUP(MIN(20,MAX(1,ROUND($E8,0))),Kargo!$A:$B,2,FALSE),99.46)) | G8: =IF($B8="","",IF(IF(N('Komisyon Tarifeleri'!AA8)>='Komisyon Tarifeleri'!I8,'Komisyon Tarifeleri'!AA8,'Komisyon Tarifeleri'!I8)="","",IF(N('Komisyon Tarifeleri'!AA8)>='Komisyon Tarifeleri'!I8,'Komisyon Tarifeleri'!AA8,'Komisyon Tarifeleri'!I8))) | H8: =IF(G8="","",IF($AM$1=2,'Komisyon Tarifeleri'!U8,'Komisyon Tarifeleri'!P8)) | I8: =IF(OR(G8="",$D8=""),"",G8*(1-H8/100)-$D8-IF(G8<=199.99,Kargo!$E$2,IF(G8<=399.99,Kargo!$E$3,$F8))) | J8: =IF(I8="","",I8/G8) | K8: =IF($B8="","",IF('Komisyon Tarifeleri'!J8="","",'Komisyon Tarifeleri'!J8)) | L8: =IF(K8="","",IF($AM$1=2,'Komisyon Tarifeleri'!V8,'Komisyon Tarifeleri'!Q8)) | M8: =IF(OR(K8="",$D8=""),"",K8*(1-L8/100)-$D8-IF(K8<=199.99,Kargo!$E$2,IF(K8<=399.99,Kargo!$E$3,$F8))) | N8: =IF(M8="","",M8/K8) | O8: =IF($B8="","",IF('Komisyon Tarifeleri'!L8="","",'Komisyon Tarifeleri'!L8)) | P8: =IF(O8="","",IF($AM$1=2,'Komisyon Tarifeleri'!W8,'Komisyon Tarifeleri'!R8)) | Q8: =IF(OR(O8="",$D8=""),"",O8*(1-P8/100)-$D8-IF(O8<=199.99,Kargo!$E$2,IF(O8<=399.99,Kargo!$E$3,$F8))) | R8: =IF(Q8="","",Q8/O8) | S8: =IF($B8="","",IF('Komisyon Tarifeleri'!N8="","",'Komisyon Tarifeleri'!N8)) | T8: =IF(S8="","",IF($AM$1=2,'Komisyon Tarifeleri'!X8,'Komisyon Tarifeleri'!S8)) | U8: =IF(OR(S8="",$D8=""),"",S8*(1-T8/100)-$D8-IF(S8<=199.99,Kargo!$E$2,IF(S8<=399.99,Kargo!$E$3,$F8))) | V8: =IF(U8="","",U8/S8) | W8: =IF($B8="","",IFERROR(VLOOKUP($C8,Hedefler!$A:$C,2,FALSE),0.04)) | X8: =IF($B8="","",IFERROR(VLOOKUP($C8,Hedefler!$A:$C,3,FALSE),0.1)) | Y8: =IF($B8="","",IFERROR(VLOOKUP($B8,Maliyetler!$A:$E,5,FALSE),"")) | Z8: =IF(OR(Y8="",Y8=0),"",Y8-1) | AA8: =IF(Z8="","",IF(Z8>='Komisyon Tarifeleri'!I8,IF($AM$1=2,'Komisyon Tarifeleri'!U8,'Komisyon Tarifeleri'!P8),IF(Z8>='Komisyon Tarifeleri'!K8,IF($AM$1=2,'Komisyon Tarifeleri'!V8,'Komisyon Tarifeleri'!Q8),IF(Z8>='Komisyon Tarifeleri'!M8,IF($AM$1=2,'Komisyon Tarifeleri'!W8,'Komisyon Tarifeleri'!R8),IF($AM$1=2,'Komisyon Tarifeleri'!X8,'Komisyon Tarifeleri'!S8))))) | AB8: =IF(OR(AA8="",$D8=""),"",Z8*(1-AA8/100)-$D8-IF(Z8<=199.99,Kargo!$E$2,IF(Z8<=399.99,Kargo!$E$3,$F8))) | AC8: =IF(AB8="","",AB8/Z8) | AD8: =IF(OR($D8="",$B8=""),"",IF(AND((1-T8/100-W8)>0,CEILING(($D8+$F8)/(1-T8/100-W8),1)<='Komisyon Tarifeleri'!N8),CEILING(($D8+$F8)/(1-T8/100-W8),1),IF(AND((1-P8/100-W8)>0,CEILING(MAX('Komisyon Tarifeleri'!M8,($D8+$F8)/(1-P8/100-W8)),1)<='Komisyon Tarifeleri'!L8),CEILING(MAX('Komisyon Tarifeleri'!M8,($D8+$F8)/(1-P8/100-W8)),1),IF(AND((1-L8/100-W8)>0,CEILING(MAX('Komisyon Tarifeleri'!K8,($D8+$F8)/(1-L8/100-W8)),1)<='Komisyon Tarifeleri'!J8),CEILING(MAX('Komisyon Tarifeleri'!K8,($D8+$F8)/(1-L8/100-W8)),1),IF((1-H8/100-W8)>0,CEILING(MAX('Komisyon Tarifeleri'!I8,($D8+$F8)/(1-H8/100-W8)),1),"İMKÂNSIZ"))))) | AE8: =IF(OR($D8="",$B8=""),"",IF(AND((1-T8/100-X8)>0,CEILING(($D8+$F8)/(1-T8/100-X8),1)<='Komisyon Tarifeleri'!N8),CEILING(($D8+$F8)/(1-T8/100-X8),1),IF(AND((1-P8/100-X8)>0,CEILING(MAX('Komisyon Tarifeleri'!M8,($D8+$F8)/(1-P8/100-X8)),1)<='Komisyon Tarifeleri'!L8),CEILING(MAX('Komisyon Tarifeleri'!M8,($D8+$F8)/(1-P8/100-X8)),1),IF(AND((1-L8/100-X8)>0,CEILING(MAX('Komisyon Tarifeleri'!K8,($D8+$F8)/(1-L8/100-X8)),1)<='Komisyon Tarifeleri'!J8),CEILING(MAX('Komisyon Tarifeleri'!K8,($D8+$F8)/(1-L8/100-X8)),1),IF((1-H8/100-X8)>0,CEILING(MAX('Komisyon Tarifeleri'!I8,($D8+$F8)/(1-H8/100-X8)),1),"İMKÂNSIZ"))))) | AF8: =IF($D8="","",IF(AND(Y8<>"",AC8<>"",AC8>=W8),Z8,IF(Y8<>"",AD8,AE8))) | AG8: =IF(OR(AF8="",AF8="İMKÂNSIZ"),"",AF8*(1-IF(AF8>='Komisyon Tarifeleri'!I8,IF($AM$1=2,'Komisyon Tarifeleri'!U8,'Komisyon Tarifeleri'!P8),IF(AF8>='Komisyon Tarifeleri'!K8,IF($AM$1=2,'Komisyon Tarifeleri'!V8,'Komisyon Tarifeleri'!Q8),IF(AF8>='Komisyon Tarifeleri'!M8,IF($AM$1=2,'Komisyon Tarifeleri'!W8,'Komisyon Tarifeleri'!R8),IF($AM$1=2,'Komisyon Tarifeleri'!X8,'Komisyon Tarifeleri'!S8))))/100)-$D8-IF(AF8<=199.99,Kargo!$E$2,IF(AF8<=399.99,Kargo!$E$3,$F8))) | AH8: =IF(AG8="","",AG8/AF8) | AI8: =IF($D8="","",IF(Y8="","BUYBOX YOK → hedef kârla min fiyat",IF(AC8>=W8,"✓ BUYBOX ALTINA GİR","BUYBOX ALTI KÂRSIZ → min kârlı fiyat"))) | AJ8: =IF($B8="","",IFERROR(VLOOKUP($B8,Maliyetler!$A:$G,6,FALSE),"")) | AK8: =IF($B8="","",IFERROR(VLOOKUP($B8,Maliyetler!$A:$G,7,FALSE),"")) | AO8: =IF($B8="","",IFERROR(VLOOKUP($B8&"",'Plus Tarifeleri'!$C:$Q,11,FALSE),"")) | AP8: =IF(AO8="","",IFERROR(IF($AM$1=2,VLOOKUP($B8&"",'Plus Tarifeleri'!$C:$Q,15,FALSE),VLOOKUP($B8&"",'Plus Tarifeleri'!$C:$Q,13,FALSE)),"")) | AQ8: =IF(OR(AO8="",AP8="",$D8=""),"",AO8*(1-AP8/100)-$D8-IF(AO8<=199.99,Kargo!$E$2,IF(AO8<=399.99,Kargo!$E$3,$F8))) | AR8: =IF(AQ8="","",AQ8/AO8) | AS8: =IF(OR(AQ8="",AG8=""),"",AQ8-AG8)
A9: =IF('Komisyon Tarifeleri'!A9="","",'Komisyon Tarifeleri'!A9) | B9: =IF('Komisyon Tarifeleri'!B9="","",'Komisyon Tarifeleri'!B9&"") | C9: =IF($B9="","",'Komisyon Tarifeleri'!F9) | D9: =IF($B9="","",IFERROR(VLOOKUP($B9,Maliyetler!$A:$E,3,FALSE),"")) | E9: =IF($B9="","",IFERROR(VLOOKUP($B9,Maliyetler!$A:$E,4,FALSE),1)) | F9: =IF($B9="","",IFERROR(VLOOKUP(MIN(20,MAX(1,ROUND($E9,0))),Kargo!$A:$B,2,FALSE),99.46)) | G9: =IF($B9="","",IF(IF(N('Komisyon Tarifeleri'!AA9)>='Komisyon Tarifeleri'!I9,'Komisyon Tarifeleri'!AA9,'Komisyon Tarifeleri'!I9)="","",IF(N('Komisyon Tarifeleri'!AA9)>='Komisyon Tarifeleri'!I9,'Komisyon Tarifeleri'!AA9,'Komisyon Tarifeleri'!I9))) | H9: =IF(G9="","",IF($AM$1=2,'Komisyon Tarifeleri'!U9,'Komisyon Tarifeleri'!P9)) | I9: =IF(OR(G9="",$D9=""),"",G9*(1-H9/100)-$D9-IF(G9<=199.99,Kargo!$E$2,IF(G9<=399.99,Kargo!$E$3,$F9))) | J9: =IF(I9="","",I9/G9) | K9: =IF($B9="","",IF('Komisyon Tarifeleri'!J9="","",'Komisyon Tarifeleri'!J9)) | L9: =IF(K9="","",IF($AM$1=2,'Komisyon Tarifeleri'!V9,'Komisyon Tarifeleri'!Q9)) | M9: =IF(OR(K9="",$D9=""),"",K9*(1-L9/100)-$D9-IF(K9<=199.99,Kargo!$E$2,IF(K9<=399.99,Kargo!$E$3,$F9))) | N9: =IF(M9="","",M9/K9) | O9: =IF($B9="","",IF('Komisyon Tarifeleri'!L9="","",'Komisyon Tarifeleri'!L9)) | P9: =IF(O9="","",IF($AM$1=2,'Komisyon Tarifeleri'!W9,'Komisyon Tarifeleri'!R9)) | Q9: =IF(OR(O9="",$D9=""),"",O9*(1-P9/100)-$D9-IF(O9<=199.99,Kargo!$E$2,IF(O9<=399.99,Kargo!$E$3,$F9))) | R9: =IF(Q9="","",Q9/O9) | S9: =IF($B9="","",IF('Komisyon Tarifeleri'!N9="","",'Komisyon Tarifeleri'!N9)) | T9: =IF(S9="","",IF($AM$1=2,'Komisyon Tarifeleri'!X9,'Komisyon Tarifeleri'!S9)) | U9: =IF(OR(S9="",$D9=""),"",S9*(1-T9/100)-$D9-IF(S9<=199.99,Kargo!$E$2,IF(S9<=399.99,Kargo!$E$3,$F9))) | V9: =IF(U9="","",U9/S9) | W9: =IF($B9="","",IFERROR(VLOOKUP($C9,Hedefler!$A:$C,2,FALSE),0.04)) | X9: =IF($B9="","",IFERROR(VLOOKUP($C9,Hedefler!$A:$C,3,FALSE),0.1)) | Y9: =IF($B9="","",IFERROR(VLOOKUP($B9,Maliyetler!$A:$E,5,FALSE),"")) | Z9: =IF(OR(Y9="",Y9=0),"",Y9-1) | AA9: =IF(Z9="","",IF(Z9>='Komisyon Tarifeleri'!I9,IF($AM$1=2,'Komisyon Tarifeleri'!U9,'Komisyon Tarifeleri'!P9),IF(Z9>='Komisyon Tarifeleri'!K9,IF($AM$1=2,'Komisyon Tarifeleri'!V9,'Komisyon Tarifeleri'!Q9),IF(Z9>='Komisyon Tarifeleri'!M9,IF($AM$1=2,'Komisyon Tarifeleri'!W9,'Komisyon Tarifeleri'!R9),IF($AM$1=2,'Komisyon Tarifeleri'!X9,'Komisyon Tarifeleri'!S9))))) | AB9: =IF(OR(AA9="",$D9=""),"",Z9*(1-AA9/100)-$D9-IF(Z9<=199.99,Kargo!$E$2,IF(Z9<=399.99,Kargo!$E$3,$F9))) | AC9: =IF(AB9="","",AB9/Z9) | AD9: =IF(OR($D9="",$B9=""),"",IF(AND((1-T9/100-W9)>0,CEILING(($D9+$F9)/(1-T9/100-W9),1)<='Komisyon Tarifeleri'!N9),CEILING(($D9+$F9)/(1-T9/100-W9),1),IF(AND((1-P9/100-W9)>0,CEILING(MAX('Komisyon Tarifeleri'!M9,($D9+$F9)/(1-P9/100-W9)),1)<='Komisyon Tarifeleri'!L9),CEILING(MAX('Komisyon Tarifeleri'!M9,($D9+$F9)/(1-P9/100-W9)),1),IF(AND((1-L9/100-W9)>0,CEILING(MAX('Komisyon Tarifeleri'!K9,($D9+$F9)/(1-L9/100-W9)),1)<='Komisyon Tarifeleri'!J9),CEILING(MAX('Komisyon Tarifeleri'!K9,($D9+$F9)/(1-L9/100-W9)),1),IF((1-H9/100-W9)>0,CEILING(MAX('Komisyon Tarifeleri'!I9,($D9+$F9)/(1-H9/100-W9)),1),"İMKÂNSIZ"))))) | AE9: =IF(OR($D9="",$B9=""),"",IF(AND((1-T9/100-X9)>0,CEILING(($D9+$F9)/(1-T9/100-X9),1)<='Komisyon Tarifeleri'!N9),CEILING(($D9+$F9)/(1-T9/100-X9),1),IF(AND((1-P9/100-X9)>0,CEILING(MAX('Komisyon Tarifeleri'!M9,($D9+$F9)/(1-P9/100-X9)),1)<='Komisyon Tarifeleri'!L9),CEILING(MAX('Komisyon Tarifeleri'!M9,($D9+$F9)/(1-P9/100-X9)),1),IF(AND((1-L9/100-X9)>0,CEILING(MAX('Komisyon Tarifeleri'!K9,($D9+$F9)/(1-L9/100-X9)),1)<='Komisyon Tarifeleri'!J9),CEILING(MAX('Komisyon Tarifeleri'!K9,($D9+$F9)/(1-L9/100-X9)),1),IF((1-H9/100-X9)>0,CEILING(MAX('Komisyon Tarifeleri'!I9,($D9+$F9)/(1-H9/100-X9)),1),"İMKÂNSIZ"))))) | AF9: =IF($D9="","",IF(AND(Y9<>"",AC9<>"",AC9>=W9),Z9,IF(Y9<>"",AD9,AE9))) | AG9: =IF(OR(AF9="",AF9="İMKÂNSIZ"),"",AF9*(1-IF(AF9>='Komisyon Tarifeleri'!I9,IF($AM$1=2,'Komisyon Tarifeleri'!U9,'Komisyon Tarifeleri'!P9),IF(AF9>='Komisyon Tarifeleri'!K9,IF($AM$1=2,'Komisyon Tarifeleri'!V9,'Komisyon Tarifeleri'!Q9),IF(AF9>='Komisyon Tarifeleri'!M9,IF($AM$1=2,'Komisyon Tarifeleri'!W9,'Komisyon Tarifeleri'!R9),IF($AM$1=2,'Komisyon Tarifeleri'!X9,'Komisyon Tarifeleri'!S9))))/100)-$D9-IF(AF9<=199.99,Kargo!$E$2,IF(AF9<=399.99,Kargo!$E$3,$F9))) | AH9: =IF(AG9="","",AG9/AF9) | AI9: =IF($D9="","",IF(Y9="","BUYBOX YOK → hedef kârla min fiyat",IF(AC9>=W9,"✓ BUYBOX ALTINA GİR","BUYBOX ALTI KÂRSIZ → min kârlı fiyat"))) | AJ9: =IF($B9="","",IFERROR(VLOOKUP($B9,Maliyetler!$A:$G,6,FALSE),"")) | AK9: =IF($B9="","",IFERROR(VLOOKUP($B9,Maliyetler!$A:$G,7,FALSE),"")) | AO9: =IF($B9="","",IFERROR(VLOOKUP($B9&"",'Plus Tarifeleri'!$C:$Q,11,FALSE),"")) | AP9: =IF(AO9="","",IFERROR(IF($AM$1=2,VLOOKUP($B9&"",'Plus Tarifeleri'!$C:$Q,15,FALSE),VLOOKUP($B9&"",'Plus Tarifeleri'!$C:$Q,13,FALSE)),"")) | AQ9: =IF(OR(AO9="",AP9="",$D9=""),"",AO9*(1-AP9/100)-$D9-IF(AO9<=199.99,Kargo!$E$2,IF(AO9<=399.99,Kargo!$E$3,$F9))) | AR9: =IF(AQ9="","",AQ9/AO9) | AS9: =IF(OR(AQ9="",AG9=""),"",AQ9-AG9)
A10: =IF('Komisyon Tarifeleri'!A10="","",'Komisyon Tarifeleri'!A10) | B10: =IF('Komisyon Tarifeleri'!B10="","",'Komisyon Tarifeleri'!B10&"") | C10: =IF($B10="","",'Komisyon Tarifeleri'!F10) | D10: =IF($B10="","",IFERROR(VLOOKUP($B10,Maliyetler!$A:$E,3,FALSE),"")) | E10: =IF($B10="","",IFERROR(VLOOKUP($B10,Maliyetler!$A:$E,4,FALSE),1)) | F10: =IF($B10="","",IFERROR(VLOOKUP(MIN(20,MAX(1,ROUND($E10,0))),Kargo!$A:$B,2,FALSE),99.46)) | G10: =IF($B10="","",IF(IF(N('Komisyon Tarifeleri'!AA10)>='Komisyon Tarifeleri'!I10,'Komisyon Tarifeleri'!AA10,'Komisyon Tarifeleri'!I10)="","",IF(N('Komisyon Tarifeleri'!AA10)>='Komisyon Tarifeleri'!I10,'Komisyon Tarifeleri'!AA10,'Komisyon Tarifeleri'!I10))) | H10: =IF(G10="","",IF($AM$1=2,'Komisyon Tarifeleri'!U10,'Komisyon Tarifeleri'!P10)) | I10: =IF(OR(G10="",$D10=""),"",G10*(1-H10/100)-$D10-IF(G10<=199.99,Kargo!$E$2,IF(G10<=399.99,Kargo!$E$3,$F10))) | J10: =IF(I10="","",I10/G10) | K10: =IF($B10="","",IF('Komisyon Tarifeleri'!J10="","",'Komisyon Tarifeleri'!J10)) | L10: =IF(K10="","",IF($AM$1=2,'Komisyon Tarifeleri'!V10,'Komisyon Tarifeleri'!Q10)) | M10: =IF(OR(K10="",$D10=""),"",K10*(1-L10/100)-$D10-IF(K10<=199.99,Kargo!$E$2,IF(K10<=399.99,Kargo!$E$3,$F10))) | N10: =IF(M10="","",M10/K10) | O10: =IF($B10="","",IF('Komisyon Tarifeleri'!L10="","",'Komisyon Tarifeleri'!L10)) | P10: =IF(O10="","",IF($AM$1=2,'Komisyon Tarifeleri'!W10,'Komisyon Tarifeleri'!R10)) | Q10: =IF(OR(O10="",$D10=""),"",O10*(1-P10/100)-$D10-IF(O10<=199.99,Kargo!$E$2,IF(O10<=399.99,Kargo!$E$3,$F10))) | R10: =IF(Q10="","",Q10/O10) | S10: =IF($B10="","",IF('Komisyon Tarifeleri'!N10="","",'Komisyon Tarifeleri'!N10)) | T10: =IF(S10="","",IF($AM$1=2,'Komisyon Tarifeleri'!X10,'Komisyon Tarifeleri'!S10)) | U10: =IF(OR(S10="",$D10=""),"",S10*(1-T10/100)-$D10-IF(S10<=199.99,Kargo!$E$2,IF(S10<=399.99,Kargo!$E$3,$F10))) | V10: =IF(U10="","",U10/S10) | W10: =IF($B10="","",IFERROR(VLOOKUP($C10,Hedefler!$A:$C,2,FALSE),0.04)) | X10: =IF($B10="","",IFERROR(VLOOKUP($C10,Hedefler!$A:$C,3,FALSE),0.1)) | Y10: =IF($B10="","",IFERROR(VLOOKUP($B10,Maliyetler!$A:$E,5,FALSE),"")) | Z10: =IF(OR(Y10="",Y10=0),"",Y10-1) | AA10: =IF(Z10="","",IF(Z10>='Komisyon Tarifeleri'!I10,IF($AM$1=2,'Komisyon Tarifeleri'!U10,'Komisyon Tarifeleri'!P10),IF(Z10>='Komisyon Tarifeleri'!K10,IF($AM$1=2,'Komisyon Tarifeleri'!V10,'Komisyon Tarifeleri'!Q10),IF(Z10>='Komisyon Tarifeleri'!M10,IF($AM$1=2,'Komisyon Tarifeleri'!W10,'Komisyon Tarifeleri'!R10),IF($AM$1=2,'Komisyon Tarifeleri'!X10,'Komisyon Tarifeleri'!S10))))) | AB10: =IF(OR(AA10="",$D10=""),"",Z10*(1-AA10/100)-$D10-IF(Z10<=199.99,Kargo!$E$2,IF(Z10<=399.99,Kargo!$E$3,$F10))) | AC10: =IF(AB10="","",AB10/Z10) | AD10: =IF(OR($D10="",$B10=""),"",IF(AND((1-T10/100-W10)>0,CEILING(($D10+$F10)/(1-T10/100-W10),1)<='Komisyon Tarifeleri'!N10),CEILING(($D10+$F10)/(1-T10/100-W10),1),IF(AND((1-P10/100-W10)>0,CEILING(MAX('Komisyon Tarifeleri'!M10,($D10+$F10)/(1-P10/100-W10)),1)<='Komisyon Tarifeleri'!L10),CEILING(MAX('Komisyon Tarifeleri'!M10,($D10+$F10)/(1-P10/100-W10)),1),IF(AND((1-L10/100-W10)>0,CEILING(MAX('Komisyon Tarifeleri'!K10,($D10+$F10)/(1-L10/100-W10)),1)<='Komisyon Tarifeleri'!J10),CEILING(MAX('Komisyon Tarifeleri'!K10,($D10+$F10)/(1-L10/100-W10)),1),IF((1-H10/100-W10)>0,CEILING(MAX('Komisyon Tarifeleri'!I10,($D10+$F10)/(1-H10/100-W10)),1),"İMKÂNSIZ"))))) | AE10: =IF(OR($D10="",$B10=""),"",IF(AND((1-T10/100-X10)>0,CEILING(($D10+$F10)/(1-T10/100-X10),1)<='Komisyon Tarifeleri'!N10),CEILING(($D10+$F10)/(1-T10/100-X10),1),IF(AND((1-P10/100-X10)>0,CEILING(MAX('Komisyon Tarifeleri'!M10,($D10+$F10)/(1-P10/100-X10)),1)<='Komisyon Tarifeleri'!L10),CEILING(MAX('Komisyon Tarifeleri'!M10,($D10+$F10)/(1-P10/100-X10)),1),IF(AND((1-L10/100-X10)>0,CEILING(MAX('Komisyon Tarifeleri'!K10,($D10+$F10)/(1-L10/100-X10)),1)<='Komisyon Tarifeleri'!J10),CEILING(MAX('Komisyon Tarifeleri'!K10,($D10+$F10)/(1-L10/100-X10)),1),IF((1-H10/100-X10)>0,CEILING(MAX('Komisyon Tarifeleri'!I10,($D10+$F10)/(1-H10/100-X10)),1),"İMKÂNSIZ"))))) | AF10: =IF($D10="","",IF(AND(Y10<>"",AC10<>"",AC10>=W10),Z10,IF(Y10<>"",AD10,AE10))) | AG10: =IF(OR(AF10="",AF10="İMKÂNSIZ"),"",AF10*(1-IF(AF10>='Komisyon Tarifeleri'!I10,IF($AM$1=2,'Komisyon Tarifeleri'!U10,'Komisyon Tarifeleri'!P10),IF(AF10>='Komisyon Tarifeleri'!K10,IF($AM$1=2,'Komisyon Tarifeleri'!V10,'Komisyon Tarifeleri'!Q10),IF(AF10>='Komisyon Tarifeleri'!M10,IF($AM$1=2,'Komisyon Tarifeleri'!W10,'Komisyon Tarifeleri'!R10),IF($AM$1=2,'Komisyon Tarifeleri'!X10,'Komisyon Tarifeleri'!S10))))/100)-$D10-IF(AF10<=199.99,Kargo!$E$2,IF(AF10<=399.99,Kargo!$E$3,$F10))) | AH10: =IF(AG10="","",AG10/AF10) | AI10: =IF($D10="","",IF(Y10="","BUYBOX YOK → hedef kârla min fiyat",IF(AC10>=W10,"✓ BUYBOX ALTINA GİR","BUYBOX ALTI KÂRSIZ → min kârlı fiyat"))) | AJ10: =IF($B10="","",IFERROR(VLOOKUP($B10,Maliyetler!$A:$G,6,FALSE),"")) | AK10: =IF($B10="","",IFERROR(VLOOKUP($B10,Maliyetler!$A:$G,7,FALSE),"")) | AO10: =IF($B10="","",IFERROR(VLOOKUP($B10&"",'Plus Tarifeleri'!$C:$Q,11,FALSE),"")) | AP10: =IF(AO10="","",IFERROR(IF($AM$1=2,VLOOKUP($B10&"",'Plus Tarifeleri'!$C:$Q,15,FALSE),VLOOKUP($B10&"",'Plus Tarifeleri'!$C:$Q,13,FALSE)),"")) | AQ10: =IF(OR(AO10="",AP10="",$D10=""),"",AO10*(1-AP10/100)-$D10-IF(AO10<=199.99,Kargo!$E$2,IF(AO10<=399.99,Kargo!$E$3,$F10))) | AR10: =IF(AQ10="","",AQ10/AO10) | AS10: =IF(OR(AQ10="",AG10=""),"",AQ10-AG10)
A11: =IF('Komisyon Tarifeleri'!A11="","",'Komisyon Tarifeleri'!A11) | B11: =IF('Komisyon Tarifeleri'!B11="","",'Komisyon Tarifeleri'!B11&"") | C11: =IF($B11="","",'Komisyon Tarifeleri'!F11) | D11: =IF($B11="","",IFERROR(VLOOKUP($B11,Maliyetler!$A:$E,3,FALSE),"")) | E11: =IF($B11="","",IFERROR(VLOOKUP($B11,Maliyetler!$A:$E,4,FALSE),1)) | F11: =IF($B11="","",IFERROR(VLOOKUP(MIN(20,MAX(1,ROUND($E11,0))),Kargo!$A:$B,2,FALSE),99.46)) | G11: =IF($B11="","",IF(IF(N('Komisyon Tarifeleri'!AA11)>='Komisyon Tarifeleri'!I11,'Komisyon Tarifeleri'!AA11,'Komisyon Tarifeleri'!I11)="","",IF(N('Komisyon Tarifeleri'!AA11)>='Komisyon Tarifeleri'!I11,'Komisyon Tarifeleri'!AA11,'Komisyon Tarifeleri'!I11))) | H11: =IF(G11="","",IF($AM$1=2,'Komisyon Tarifeleri'!U11,'Komisyon Tarifeleri'!P11)) | I11: =IF(OR(G11="",$D11=""),"",G11*(1-H11/100)-$D11-IF(G11<=199.99,Kargo!$E$2,IF(G11<=399.99,Kargo!$E$3,$F11))) | J11: =IF(I11="","",I11/G11) | K11: =IF($B11="","",IF('Komisyon Tarifeleri'!J11="","",'Komisyon Tarifeleri'!J11)) | L11: =IF(K11="","",IF($AM$1=2,'Komisyon Tarifeleri'!V11,'Komisyon Tarifeleri'!Q11)) | M11: =IF(OR(K11="",$D11=""),"",K11*(1-L11/100)-$D11-IF(K11<=199.99,Kargo!$E$2,IF(K11<=399.99,Kargo!$E$3,$F11))) | N11: =IF(M11="","",M11/K11) | O11: =IF($B11="","",IF('Komisyon Tarifeleri'!L11="","",'Komisyon Tarifeleri'!L11)) | P11: =IF(O11="","",IF($AM$1=2,'Komisyon Tarifeleri'!W11,'Komisyon Tarifeleri'!R11)) | Q11: =IF(OR(O11="",$D11=""),"",O11*(1-P11/100)-$D11-IF(O11<=199.99,Kargo!$E$2,IF(O11<=399.99,Kargo!$E$3,$F11))) | R11: =IF(Q11="","",Q11/O11) | S11: =IF($B11="","",IF('Komisyon Tarifeleri'!N11="","",'Komisyon Tarifeleri'!N11)) | T11: =IF(S11="","",IF($AM$1=2,'Komisyon Tarifeleri'!X11,'Komisyon Tarifeleri'!S11)) | U11: =IF(OR(S11="",$D11=""),"",S11*(1-T11/100)-$D11-IF(S11<=199.99,Kargo!$E$2,IF(S11<=399.99,Kargo!$E$3,$F11))) | V11: =IF(U11="","",U11/S11) | W11: =IF($B11="","",IFERROR(VLOOKUP($C11,Hedefler!$A:$C,2,FALSE),0.04)) | X11: =IF($B11="","",IFERROR(VLOOKUP($C11,Hedefler!$A:$C,3,FALSE),0.1)) | Y11: =IF($B11="","",IFERROR(VLOOKUP($B11,Maliyetler!$A:$E,5,FALSE),"")) | Z11: =IF(OR(Y11="",Y11=0),"",Y11-1) | AA11: =IF(Z11="","",IF(Z11>='Komisyon Tarifeleri'!I11,IF($AM$1=2,'Komisyon Tarifeleri'!U11,'Komisyon Tarifeleri'!P11),IF(Z11>='Komisyon Tarifeleri'!K11,IF($AM$1=2,'Komisyon Tarifeleri'!V11,'Komisyon Tarifeleri'!Q11),IF(Z11>='Komisyon Tarifeleri'!M11,IF($AM$1=2,'Komisyon Tarifeleri'!W11,'Komisyon Tarifeleri'!R11),IF($AM$1=2,'Komisyon Tarifeleri'!X11,'Komisyon Tarifeleri'!S11))))) | AB11: =IF(OR(AA11="",$D11=""),"",Z11*(1-AA11/100)-$D11-IF(Z11<=199.99,Kargo!$E$2,IF(Z11<=399.99,Kargo!$E$3,$F11))) | AC11: =IF(AB11="","",AB11/Z11) | AD11: =IF(OR($D11="",$B11=""),"",IF(AND((1-T11/100-W11)>0,CEILING(($D11+$F11)/(1-T11/100-W11),1)<='Komisyon Tarifeleri'!N11),CEILING(($D11+$F11)/(1-T11/100-W11),1),IF(AND((1-P11/100-W11)>0,CEILING(MAX('Komisyon Tarifeleri'!M11,($D11+$F11)/(1-P11/100-W11)),1)<='Komisyon Tarifeleri'!L11),CEILING(MAX('Komisyon Tarifeleri'!M11,($D11+$F11)/(1-P11/100-W11)),1),IF(AND((1-L11/100-W11)>0,CEILING(MAX('Komisyon Tarifeleri'!K11,($D11+$F11)/(1-L11/100-W11)),1)<='Komisyon Tarifeleri'!J11),CEILING(MAX('Komisyon Tarifeleri'!K11,($D11+$F11)/(1-L11/100-W11)),1),IF((1-H11/100-W11)>0,CEILING(MAX('Komisyon Tarifeleri'!I11,($D11+$F11)/(1-H11/100-W11)),1),"İMKÂNSIZ"))))) | AE11: =IF(OR($D11="",$B11=""),"",IF(AND((1-T11/100-X11)>0,CEILING(($D11+$F11)/(1-T11/100-X11),1)<='Komisyon Tarifeleri'!N11),CEILING(($D11+$F11)/(1-T11/100-X11),1),IF(AND((1-P11/100-X11)>0,CEILING(MAX('Komisyon Tarifeleri'!M11,($D11+$F11)/(1-P11/100-X11)),1)<='Komisyon Tarifeleri'!L11),CEILING(MAX('Komisyon Tarifeleri'!M11,($D11+$F11)/(1-P11/100-X11)),1),IF(AND((1-L11/100-X11)>0,CEILING(MAX('Komisyon Tarifeleri'!K11,($D11+$F11)/(1-L11/100-X11)),1)<='Komisyon Tarifeleri'!J11),CEILING(MAX('Komisyon Tarifeleri'!K11,($D11+$F11)/(1-L11/100-X11)),1),IF((1-H11/100-X11)>0,CEILING(MAX('Komisyon Tarifeleri'!I11,($D11+$F11)/(1-H11/100-X11)),1),"İMKÂNSIZ"))))) | AF11: =IF($D11="","",IF(AND(Y11<>"",AC11<>"",AC11>=W11),Z11,IF(Y11<>"",AD11,AE11))) | AG11: =IF(OR(AF11="",AF11="İMKÂNSIZ"),"",AF11*(1-IF(AF11>='Komisyon Tarifeleri'!I11,IF($AM$1=2,'Komisyon Tarifeleri'!U11,'Komisyon Tarifeleri'!P11),IF(AF11>='Komisyon Tarifeleri'!K11,IF($AM$1=2,'Komisyon Tarifeleri'!V11,'Komisyon Tarifeleri'!Q11),IF(AF11>='Komisyon Tarifeleri'!M11,IF($AM$1=2,'Komisyon Tarifeleri'!W11,'Komisyon Tarifeleri'!R11),IF($AM$1=2,'Komisyon Tarifeleri'!X11,'Komisyon Tarifeleri'!S11))))/100)-$D11-IF(AF11<=199.99,Kargo!$E$2,IF(AF11<=399.99,Kargo!$E$3,$F11))) | AH11: =IF(AG11="","",AG11/AF11) | AI11: =IF($D11="","",IF(Y11="","BUYBOX YOK → hedef kârla min fiyat",IF(AC11>=W11,"✓ BUYBOX ALTINA GİR","BUYBOX ALTI KÂRSIZ → min kârlı fiyat"))) | AJ11: =IF($B11="","",IFERROR(VLOOKUP($B11,Maliyetler!$A:$G,6,FALSE),"")) | AK11: =IF($B11="","",IFERROR(VLOOKUP($B11,Maliyetler!$A:$G,7,FALSE),"")) | AO11: =IF($B11="","",IFERROR(VLOOKUP($B11&"",'Plus Tarifeleri'!$C:$Q,11,FALSE),"")) | AP11: =IF(AO11="","",IFERROR(IF($AM$1=2,VLOOKUP($B11&"",'Plus Tarifeleri'!$C:$Q,15,FALSE),VLOOKUP($B11&"",'Plus Tarifeleri'!$C:$Q,13,FALSE)),"")) | AQ11: =IF(OR(AO11="",AP11="",$D11=""),"",AO11*(1-AP11/100)-$D11-IF(AO11<=199.99,Kargo!$E$2,IF(AO11<=399.99,Kargo!$E$3,$F11))) | AR11: =IF(AQ11="","",AQ11/AO11) | AS11: =IF(OR(AQ11="",AG11=""),"",AQ11-AG11)
